<?xml version="1.0"?>
<robot xmlns:xacro="http://www.ros.org/wiki/xacro">
  <xacro:macro name="borunte_macro" params="prefix">
    <material name="Black">
      <color rgba="0.1 0.1 0.1 1.0"/>
    </material>
    <material name="DarkRed">
      <color rgba="0.5 0.0 0.0 1.0"/>
    </material>

    <!-- link list -->
    <link name="${prefix}base_link">
      <visual>
        <geometry>
          <mesh filename="package://borunte_support/meshes/base_link.stl"/>
        </geometry>
        <origin rpy="0.0 0 0.0" xyz="0 0 0"/>
        <material name="Black"/>
      </visual>
      <collision>
        <geometry>
          <mesh filename="package://borunte_support/meshes/base_link_collision.stl"/>
        </geometry>
        <origin rpy="0.0 0 0.0" xyz="0 0 0"/>
      </collision>
    </link>
    <link name="${prefix}link_1">
      <visual>
        <geometry>
          <mesh filename="package://borunte_support/meshes/link_1.stl"/>
        </geometry>
        <origin rpy="0.0 0 0.0" xyz="0 0 0"/>
        <material name="DarkRed"/>
      </visual>
      <collision>
        <geometry>
          <mesh filename="package://borunte_support/meshes/link_1_collision.stl"/>
        </geometry>
        <origin rpy="0.0 0 0.0" xyz="0 0 0"/>
      </collision>
      <inertial>
        <mass value="100"/>
        <inertia ixx="1.0" ixy="0.0" ixz="0.0" iyy="1.0" iyz="0.0" izz="1.0"/>
      </inertial>
    </link>

    <link name="${prefix}link_2">
      <visual>
        <geometry>
          <mesh filename="package://borunte_support/meshes/link_2.stl"/>
        </geometry>
        <origin rpy="0.0 0 0.0" xyz="0 0 0"/>
        <material name="DarkRed"/>
      </visual>
      <collision>
        <geometry>
          <mesh filename="package://borunte_support/meshes/link_2_collision.stl"/>
        </geometry>
        <origin rpy="0.0 0 0.0" xyz="0 0 0"/>
      </collision>
      <inertial>
        <mass value="100"/>
        <inertia ixx="1.0" ixy="0.0" ixz="0.0" iyy="1.0" iyz="0.0" izz="1.0"/>
      </inertial>
    </link>

    <link name="${prefix}link_3">
      <visual>
        <geometry>
          <mesh filename="package://borunte_support/meshes/link_3.stl"/>
        </geometry>
        <origin rpy="0.0 0 0.0" xyz="0 0 0"/>
        <material name="DarkRed"/>
      </visual>
      <collision>
        <geometry>
          <mesh filename="package://borunte_support/meshes/link_3_collision.stl"/>
        </geometry>
        <origin rpy="0.0 0 0.0" xyz="-0 0 0"/>
      </collision>
      <inertial>
        <mass value="100"/>
        <inertia ixx="1.0" ixy="0.0" ixz="0.0" iyy="1.0" iyz="0.0" izz="1.0"/>
      </inertial>
    </link>


    <link name="${prefix}link_4">
      <visual>
        <geometry>
          <mesh filename="package://borunte_support/meshes/link_4.stl"/>
        </geometry>
        <origin rpy="0.0 0.0 0.0" xyz="0 0 0"/>
        <material name="DarkRed"/>
      </visual>
      <collision>
        <geometry>
          <mesh filename="package://borunte_support/meshes/link_4_collision.stl"/>
        </geometry>
        <origin rpy="0.0 0 0.0" xyz="0 0 0"/>
      </collision>
      <inertial>
        <mass value="100"/>
        <inertia ixx="1.0" ixy="0.0" ixz="0.0" iyy="1.0" iyz="0.0" izz="1.0"/>
      </inertial>
    </link>

    <link name="${prefix}link_5">
      <visual>
        <geometry>
          <mesh filename="package://borunte_support/meshes/link_5.stl"/>
        </geometry>
        <origin rpy="0 0 0" xyz="0 0 0"/>
        <material name="DarkRed"/>
      </visual>
      <collision>
        <geometry>
          <mesh filename="package://borunte_support/meshes/link_5_collision.stl"/>
        </geometry>
        <origin rpy="0 0 0" xyz="0 0 0"/>
      </collision>
      <inertial>
        <mass value="100"/>
        <inertia ixx="1.0" ixy="0.0" ixz="0.0" iyy="1.0" iyz="0.0" izz="1.0"/>
      </inertial>
    </link>

    <link name="${prefix}link_6">
      <visual>
        <geometry>
          <mesh filename="package://borunte_support/meshes/link_6.stl"/>
        </geometry>
        <origin rpy="0 0 0.0" xyz="0 0 0"/>
        <material name="DarkRed"/>
      </visual>
      <collision>
        <geometry>
          <mesh filename="package://borunte_support/meshes/link_6_collision.stl"/>
        </geometry>
        <origin rpy="0 0 0.0" xyz="0 0 0"/>
      </collision>
      <inertial>
        <mass value="100"/>
        <inertia ixx="1.0" ixy="0.0" ixz="0.0" iyy="1.0" iyz="0.0" izz="1.0"/>
      </inertial>
    </link>

    <!-- joint list -->
    <joint name="${prefix}joint_1" type="revolute">
      <limit effort="1000.0" lower="-3.076" upper="3.076" velocity="3.14"/>
      <parent link="base_link"/>
      <child link="link_1"/>
      <axis xyz="0 0 1"/>
      <origin rpy="0.0 0.0 0.0" xyz="0 0 0.24"/>
    </joint>

    <joint name="${prefix}joint_2" type="revolute">
      <limit effort="1000.0" lower="-1.74" upper="2.35" velocity="1.0"/>
      <parent link="link_1"/>
      <child link="link_2"/>
      <axis xyz="0 1 0"/>
      <origin rpy="0.0 0.0 0.0" xyz="0.07 0.08 0.165"/>
    </joint>

    <joint name="${prefix}joint_3" type="revolute">
      <limit effort="1000.0" lower="-2.094" upper="1.570" velocity="1.3"/>
      <parent link="link_2"/>
      <child link="link_3"/>
      <axis xyz="0 1 0"/>
      <origin rpy="0.0 ${pi/2.0} 0.0" xyz="0.0 0.0 0.39"/>
    </joint>

    <joint name="${prefix}joint_4" type="revolute">
      <limit effort="1000.0" lower="-2.094" upper="2.094" velocity="2.0"/>
      <parent link="link_3"/>
      <child link="link_4"/>
      <axis xyz="0 0 1"/>
      <origin rpy="0.0 0.0 0.0" xyz="-0.125 -0.1 0.095"/>
    </joint>
    <joint name="${prefix}joint_5" type="revolute">
      <limit effort="1000.0" lower="-1.919" upper="2.094" velocity="2.35"/>
      <parent link="link_4"/>
      <child link="link_5"/>
      <axis xyz="0 1 0"/>
      <origin rpy="0.0 0.0 0.0" xyz="0.0 -0.0 0.31"/>
    </joint>

    <joint name="${prefix}joint_6" type="revolute">
      <limit effort="1000.0" lower="${-pi}" upper="${pi}" velocity="2.35"/>
      <parent link="link_5"/>
      <child link="link_6"/>
      <axis xyz="0 0 1"/>
      <origin rpy="0.0 0.0 0.0" xyz="0 0 0.089"/>
    </joint>


    <!-- ROS-Industrial 'base' frame: base_link to Fanuc World Coordinates transform -->
    <link name="${prefix}base" />
    <joint name="${prefix}base_link-base" type="fixed">
      <origin xyz="0 0 0" rpy="0 0 0"/>
      <axis xyz="0 0 1"/>
      <parent link="${prefix}base_link"/>
      <child link="${prefix}base"/>
    </joint>

    <!-- ROS-Industrial 'flange' frame: attachment point for EEF models -->
    <link name="${prefix}flange"/>
    <joint name="${prefix}joint_6-flange" type="fixed">
      <origin xyz="0 0 0.015" rpy="0 0 0" />
      <parent link="${prefix}link_6" />
      <child link="${prefix}flange" />
    </joint>

  </xacro:macro>
</robot>
